Workbook

Sheet Painel
A1: Painel — acompanhamento do preenchimento
A2: Atualiza sozinho a partir da aba "Por Disciplina". ✔ = disciplina já preencheu informações no trimestre.
A4: Disciplina | B4: 1º Trimestre | C4: 2º Trimestre | D4: 3º Trimestre | E4: Avisos no mural | F4: Itens na agenda
A5: Biologia | B5: =IF(COUNTA('Por Disciplina'!C5:H5)=0,"Pendente","✔ "&COUNTA('Por Disciplina'!C5:H5)&"/6 campos") -> Pendente | C5: =IF(COUNTA('Por Disciplina'!C22:H22)=0,"Pendente","✔ "&COUNTA('Por Disciplina'!C22:H22)&"/6 campos") -> Pendente | D5: =IF(COUNTA('Por Disciplina'!C39:H39)=0,"Pendente","✔ "&COUNTA('Por Disciplina'!C39:H39)&"/6 campos") -> Pendente | E5: =COUNTIF('Mural de Avisos'!$D$5:$D$104,A5) -> 0 | F5: =COUNTIF(Agenda!$C$5:$C$204,A5) -> 0
A6: Educação Física | B6: =IF(COUNTA('Por Disciplina'!C6:H6)=0,"Pendente","✔ "&COUNTA('Por Disciplina'!C6:H6)&"/6 campos") -> Pendente | C6: =IF(COUNTA('Por Disciplina'!C23:H23)=0,"Pendente","✔ "&COUNTA('Por Disciplina'!C23:H23)&"/6 campos") -> Pendente | D6: =IF(COUNTA('Por Disciplina'!C40:H40)=0,"Pendente","✔ "&COUNTA('Por Disciplina'!C40:H40)&"/6 campos") -> Pendente | E6: =COUNTIF('Mural de Avisos'!$D$5:$D$104,A6) -> 0 | F6: =COUNTIF(Agenda!$C$5:$C$204,A6) -> 0
A7: Ensino Religioso | B7: =IF(COUNTA('Por Disciplina'!C7:H7)=0,"Pendente","✔ "&COUNTA('Por Disciplina'!C7:H7)&"/6 campos") -> Pendente | C7: =IF(COUNTA('Por Disciplina'!C24:H24)=0,"Pendente","✔ "&COUNTA('Por Disciplina'!C24:H24)&"/6 campos") -> Pendente | D7: =IF(COUNTA('Por Disciplina'!C41:H41)=0,"Pendente","✔ "&COUNTA('Por Disciplina'!C41:H41)&"/6 campos") -> Pendente | E7: =COUNTIF('Mural de Avisos'!$D$5:$D$104,A7) -> 0 | F7: =COUNTIF(Agenda!$C$5:$C$204,A7) -> 0
A8: Espanhol | B8: =IF(COUNTA('Por Disciplina'!C8:H8)=0,"Pendente","✔ "&COUNTA('Por Disciplina'!C8:H8)&"/6 campos") -> Pendente | C8: =IF(COUNTA('Por Disciplina'!C25:H25)=0,"Pendente","✔ "&COUNTA('Por Disciplina'!C25:H25)&"/6 campos") -> Pendente | D8: =IF(COUNTA('Por Disciplina'!C42:H42)=0,"Pendente","✔ "&COUNTA('Por Disciplina'!C42:H42)&"/6 campos") -> Pendente | E8: =COUNTIF('Mural de Avisos'!$D$5:$D$104,A8) -> 0 | F8: =COUNTIF(Agenda!$C$5:$C$204,A8) -> 0
A9: Filosofia | B9: =IF(COUNTA('Por Disciplina'!C9:H9)=0,"Pendente","✔ "&COUNTA('Por Disciplina'!C9:H9)&"/6 campos") -> Pendente | C9: =IF(COUNTA('Por Disciplina'!C26:H26)=0,"Pendente","✔ "&COUNTA('Por Disciplina'!C26:H26)&"/6 campos") -> Pendente | D9: =IF(COUNTA('Por Disciplina'!C43:H43)=0,"Pendente","✔ "&COUNTA('Por Disciplina'!C43:H43)&"/6 campos") -> Pendente | E9: =COUNTIF('Mural de Avisos'!$D$5:$D$104,A9) -> 0 | F9: =COUNTIF(Agenda!$C$5:$C$204,A9) -> 0
A10: Física | B10: =IF(COUNTA('Por Disciplina'!C10:H10)=0,"Pendente","✔ "&COUNTA('Por Disciplina'!C10:H10)&"/6 campos") -> Pendente | C10: =IF(COUNTA('Por Disciplina'!C27:H27)=0,"Pendente","✔ "&COUNTA('Por Disciplina'!C27:H27)&"/6 campos") -> Pendente | D10: =IF(COUNTA('Por Disciplina'!C44:H44)=0,"Pendente","✔ "&COUNTA('Por Disciplina'!C44:H44)&"/6 campos") -> Pendente | E10: =COUNTIF('Mural de Avisos'!$D$5:$D$104,A10) -> 0 | F10: =COUNTIF(Agenda!$C$5:$C$204,A10) -> 0
A11: Geografia | B11: =IF(COUNTA('Por Disciplina'!C11:H11)=0,"Pendente","✔ "&COUNTA('Por Disciplina'!C11:H11)&"/6 campos") -> Pendente | C11: =IF(COUNTA('Por Disciplina'!C28:H28)=0,"Pendente","✔ "&COUNTA('Por Disciplina'!C28:H28)&"/6 campos") -> Pendente | D11: =IF(COUNTA('Por Disciplina'!C45:H45)=0,"Pendente","✔ "&COUNTA('Por Disciplina'!C45:H45)&"/6 campos") -> Pendente | E11: =COUNTIF('Mural de Avisos'!$D$5:$D$104,A11) -> 0 | F11: =COUNTIF(Agenda!$C$5:$C$204,A11) -> 0
A12: História | B12: =IF(COUNTA('Por Disciplina'!C12:H12)=0,"Pendente","✔ "&COUNTA('Por Disciplina'!C12:H12)&"/6 campos") -> Pendente | C12: =IF(COUNTA('Por Disciplina'!C29:H29)=0,"Pendente","✔ "&COUNTA('Por Disciplina'!C29:H29)&"/6 campos") -> Pendente | D12: =IF(COUNTA('Por Disciplina'!C46:H46)=0,"Pendente","✔ "&COUNTA('Por Disciplina'!C46:H46)&"/6 campos") -> Pendente | E12: =COUNTIF('Mural de Avisos'!$D$5:$D$104,A12) -> 0 | F12: =COUNTIF(Agenda!$C$5:$C$204,A12) -> 0
A13: Inglês | B13: =IF(COUNTA('Por Disciplina'!C13:H13)=0,"Pendente","✔ "&COUNTA('Por Disciplina'!C13:H13)&"/6 campos") -> Pendente | C13: =IF(COUNTA('Por Disciplina'!C30:H30)=0,"Pendente","✔ "&COUNTA('Por Disciplina'!C30:H30)&"/6 campos") -> Pendente | D13: =IF(COUNTA('Por Disciplina'!C47:H47)=0,"Pendente","✔ "&COUNTA('Por Disciplina'!C47:H47)&"/6 campos") -> Pendente | E13: =COUNTIF('Mural de Avisos'!$D$5:$D$104,A13) -> 0 | F13: =COUNTIF(Agenda!$C$5:$C$204,A13) -> 0
A14: LP | B14: =IF(COUNTA('Por Disciplina'!C14:H14)=0,"Pendente","✔ "&COUNTA('Por Disciplina'!C14:H14)&"/6 campos") -> Pendente | C14: =IF(COUNTA('Por Disciplina'!C31:H31)=0,"Pendente","✔ "&COUNTA('Por Disciplina'!C31:H31)&"/6 campos") -> Pendente | D14: =IF(COUNTA('Por Disciplina'!C48:H48)=0,"Pendente","✔ "&COUNTA('Por Disciplina'!C48:H48)&"/6 campos") -> Pendente | E14: =COUNTIF('Mural de Avisos'!$D$5:$D$104,A14) -> 0 | F14: =COUNTIF(Agenda!$C$5:$C$204,A14) -> 0
A15: Matemática | B15: =IF(COUNTA('Por Disciplina'!C15:H15)=0,"Pendente","✔ "&COUNTA('Por Disciplina'!C15:H15)&"/6 campos") -> Pendente | C15: =IF(COUNTA('Por Disciplina'!C32:H32)=0,"Pendente","✔ "&COUNTA('Por Disciplina'!C32:H32)&"/6 campos") -> Pendente | D15: =IF(COUNTA('Por Disciplina'!C49:H49)=0,"Pendente","✔ "&COUNTA('Por Disciplina'!C49:H49)&"/6 campos") -> Pendente | E15: =COUNTIF('Mural de Avisos'!$D$5:$D$104,A15) -> 0 | F15: =COUNTIF(Agenda!$C$5:$C$204,A15) -> 0
A16: Projeto de vida | B16: =IF(COUNTA('Por Disciplina'!C16:H16)=0,"Pendente","✔ "&COUNTA('Por Disciplina'!C16:H16)&"/6 campos") -> Pendente | C16: =IF(COUNTA('Por Disciplina'!C33:H33)=0,"Pendente","✔ "&COUNTA('Por Disciplina'!C33:H33)&"/6 campos") -> Pendente | D16: =IF(COUNTA('Por Disciplina'!C50:H50)=0,"Pendente","✔ "&COUNTA('Por Disciplina'!C50:H50)&"/6 campos") -> Pendente | E16: =COUNTIF('Mural de Avisos'!$D$5:$D$104,A16) -> 0 | F16: =COUNTIF(Agenda!$C$5:$C$204,A16) -> 0
... A19: Oficinas | B19: =IF(COUNTA('Por Disciplina'!C19:H19)=0,"Pendente","✔ "&COUNTA('Por Disciplina'!C19:H19)&"/6 campos") -> Pendente | C19: =IF(COUNTA('Por Disciplina'!C36:H36)=0,"Pendente","✔ "&COUNTA('Por Disciplina'!C36:H36)&"/6 campos") -> Pendente | D19: =IF(COUNTA('Por Disciplina'!C53:H53)=0,"Pendente","✔ "&COUNTA('Por Disciplina'!C53:H53)&"/6 campos") -> Pendente | E19: =COUNTIF('Mural de Avisos'!$D$5:$D$104,A19) -> 0 | F19: =COUNTIF(Agenda!$C$5:$C$204,A19) -> 0
A20: Disciplinas com informações | B20: =COUNTIF(B5:B19,"✔*")&" de 15" -> 0 de 15 | C20: =COUNTIF(C5:C19,"✔*")&" de 15" -> 0 de 15 | D20: =COUNTIF(D5:D19,"✔*")&" de 15" -> 0 de 15 | E20: =SUM(E5:E19) -> 0 | F20: =SUM(F5:F19) -> 0
A23: Como usar
A24: 1. Por Disciplina — cada professor(a) preenche a linha da sua disciplina no trimestre (células amarelo-claro). Não altere a coluna de disciplinas.
A25: 2. Mural de Avisos — recados que valem para TODOS (como o aviso sobre o período eleitoral, já transferido para lá). Escreva uma vez só, sem repetir em cada disciplina.
A26: 3. Agenda — provas, entregas e eventos com data. A coluna "Outras atividades no mesmo dia" alerta choques de datas entre disciplinas.
A27: 4. Painel — mostra quem já preencheu e quem está pendente em cada trimestre. Não precisa editar.
A28: 5. Para trabalhar em conjunto, salve no Google Drive / OneDrive e compartilhe com permissão de edição; todos verão as atualizações em tempo real.

Sheet Por Disciplina
A1: Planejamento compartilhado — 1º Ano
A2: Cada disciplina preenche a própria linha (células em amarelo-claro). Avisos gerais vão na aba "Mural de Avisos"; datas de provas/eventos na aba "Agenda".
A4: Trimestre | B4: Disciplina | C4: Professor(a) responsável | D4: Informações para todos (recados, combinados, alertas) | E4: Conteúdos / temas do trimestre | F4: Avaliações e datas | G4: Projetos / interdisciplinaridade | H4: Precisa de apoio de outras disciplinas? Quais? | I4: Status | J4: Atualizado por | K4: Data da atualização
A5: 1º Trimestre | B5: Biologia
B6: Educação Física
B7: Ensino Religioso
B8: Espanhol
B9: Filosofia
B10: Física
B11: Geografia
B12: História
B13: Inglês
B14: LP
B15: Matemática
B16: Projeto de vida
B17: Química
... B19: Oficinas
A21: Trimestre | B21: Disciplina | C21: Professor(a) responsável | D21: Informações para todos (recados, combinados, alertas) | E21: Conteúdos / temas do trimestre | F21: Avaliações e datas | G21: Projetos / interdisciplinaridade | H21: Precisa de apoio de outras disciplinas? Quais? | I21: Status | J21: Atualizado por | K21: Data da atualização
A22: 2º Trimestre | B22: Biologia
B23: Educação Física
B24: Ensino Religioso
B25: Espanhol
B26: Filosofia
B27: Física
B28: Geografia
B29: História
B30: Inglês
B31: LP
B32: Matemática
B33: Projeto de vida
B34: Química
... B36: Oficinas
A38: Trimestre | B38: Disciplina | C38: Professor(a) responsável | D38: Informações para todos (recados, combinados, alertas) | E38: Conteúdos / temas do trimestre | F38: Avaliações e datas | G38: Projetos / interdisciplinaridade | H38: Precisa de apoio de outras disciplinas? Quais? | I38: Status | J38: Atualizado por | K38: Data da atualização
A39: 3º Trimestre | B39: Biologia
B40: Educação Física
B41: Ensino Religioso
B42: Espanhol
B43: Filosofia
B44: Física
B45: Geografia
...

Sheet Mural de Avisos
A1: Mural de Avisos — informações compartilhadas com todos
A2: Inclua um aviso por linha (o mais recente embaixo). Use para recados que valem para todas as disciplinas, evitando copiar o mesmo texto em várias linhas.
A4: Nº | B4: Data | C4: Trimestre | D4: Enviado por (disciplina/setor) | E4: Autor(a) | F4: Assunto | G4: Mensagem para todos | H4: Prioridade | I4: Válido até | J4: Ciência / comentários
A5: =IF(G5="","",ROW()-4) -> 1 | C5: 1º Trimestre | D5: Direção | F5: Postura imparcial no período eleitoral (Código de Ética, item 3.7) | G5: Prezados colaboradores, Com a proximidade do segundo turno das eleições, em um contexto de intensa polarização política, consideramos importante reafirmar o caráter apartidário da instituição e reforçar o respeito à pluralidade de ideias, à liberdade de pensamento e às escolhas individuais. Como instituição educativa, nosso papel é contribuir para a formação integral dos estudantes, incentivando o pensamento crítico, o diálogo respeitoso e o exercício consciente da cidadania, sem favorecer qualquer partido ou candidato. Nesse sentido, lembramos que o nosso Código de Ética, Cultura e Cuidado estabelece, no item 3.7, a seguinte orientação: “Adotar postura imparcial em relação a assuntos políticos, partidários ou similares no ambiente escolar. É proibido realizar qualquer tipo de evento ou manifestação política dentro das instalações do Colégio, evitando interferir na orientação ou escolha política individual”. Pedimos, portanto, que todos os colaboradores tenham especial atenção às suas manifestações no ambiente escolar, inclusive por meio de vestimentas e acessórios, em todas as atividades oficiais do colégio, com ou sem presença de estudantes. Essa orientação não pretende restringir as convicções pessoais ou a liberdade de pensamento de ninguém, mas assegurar um ambiente de respeito à diversidade de opiniões. Contamos com a compreensão e a colaboração de todos para que o Colégio continue sendo um espaço de convivência harmoniosa e formação para a cidadania. | H5: Alta
A6: =IF(G6="","",ROW()-4)
A7: =IF(G7="","",ROW()-4)
A8: =IF(G8="","",ROW()-4)
A9: =IF(G9="","",ROW()-4)
A10: =IF(G10="","",ROW()-4)
A11: =IF(G11="","",ROW()-4)
A12: =IF(G12="","",ROW()-4)
A13: =IF(G13="","",ROW()-4)
A14: =IF(G14="","",ROW()-4)
A15: =IF(G15="","",ROW()-4)
A16: =IF(G16="","",ROW()-4)
A17: =IF(G17="","",ROW()-4)
... A104: =IF(G104="","",ROW()-4)

Sheet Agenda
A1: Agenda compartilhada — avaliações, entregas e eventos
A2: Registre datas importantes para que todas as disciplinas vejam. A última coluna é automática e avisa quando já há outra atividade marcada no mesmo dia.
A4: Data | B4: Trimestre | C4: Disciplina | D4: Tipo | E4: Descrição | F4: Turma(s) | G4: Responsável | H4: Outras atividades no mesmo dia
H5: =IF(A5="","",IF(COUNTIF($A$5:$A$204,A5)>1,"⚠ "&(COUNTIF($A$5:$A$204,A5)-1)&" outra(s)","—"))
H6: =IF(A6="","",IF(COUNTIF($A$5:$A$204,A6)>1,"⚠ "&(COUNTIF($A$5:$A$204,A6)-1)&" outra(s)","—"))
H7: =IF(A7="","",IF(COUNTIF($A$5:$A$204,A7)>1,"⚠ "&(COUNTIF($A$5:$A$204,A7)-1)&" outra(s)","—"))
H8: =IF(A8="","",IF(COUNTIF($A$5:$A$204,A8)>1,"⚠ "&(COUNTIF($A$5:$A$204,A8)-1)&" outra(s)","—"))
H9: =IF(A9="","",IF(COUNTIF($A$5:$A$204,A9)>1,"⚠ "&(COUNTIF($A$5:$A$204,A9)-1)&" outra(s)","—"))
H10: =IF(A10="","",IF(COUNTIF($A$5:$A$204,A10)>1,"⚠ "&(COUNTIF($A$5:$A$204,A10)-1)&" outra(s)","—"))
H11: =IF(A11="","",IF(COUNTIF($A$5:$A$204,A11)>1,"⚠ "&(COUNTIF($A$5:$A$204,A11)-1)&" outra(s)","—"))
H12: =IF(A12="","",IF(COUNTIF($A$5:$A$204,A12)>1,"⚠ "&(COUNTIF($A$5:$A$204,A12)-1)&" outra(s)","—"))
H13: =IF(A13="","",IF(COUNTIF($A$5:$A$204,A13)>1,"⚠ "&(COUNTIF($A$5:$A$204,A13)-1)&" outra(s)","—"))
H14: =IF(A14="","",IF(COUNTIF($A$5:$A$204,A14)>1,"⚠ "&(COUNTIF($A$5:$A$204,A14)-1)&" outra(s)","—"))
H15: =IF(A15="","",IF(COUNTIF($A$5:$A$204,A15)>1,"⚠ "&(COUNTIF($A$5:$A$204,A15)-1)&" outra(s)","—"))
H16: =IF(A16="","",IF(COUNTIF($A$5:$A$204,A16)>1,"⚠ "&(COUNTIF($A$5:$A$204,A16)-1)&" outra(s)","—"))
... H204: =IF(A204="","",IF(COUNTIF($A$5:$A$204,A204)>1,"⚠ "&(COUNTIF($A$5:$A$204,A204)-1)&" outra(s)","—"))

Sheet Listas
A1: Disciplinas | B1: Setores | C1: Trimestres | D1: Tipos | E1: Prioridade | F1: Status | H1: Para incluir novas opções nos menus, acrescente-as no fim da coluna e ajuste o intervalo em Dados > Validação.
A2: Biologia | B2: Biologia | C2: 1º Trimestre | D2: Avaliação | E2: Alta | F2: Pendente
A3: Educação Física | B3: Educação Física | C3: 2º Trimestre | D3: Trabalho / Entrega | E3: Média | F3: Em andamento
A4: Ensino Religioso | B4: Ensino Religioso | C4: 3º Trimestre | D4: Projeto interdisciplinar | E4: Baixa | F4: Concluído
A5: Espanhol | B5: Espanhol | D5: Evento
A6: Filosofia | B6: Filosofia | D6: Saída pedagógica
A7: Física | B7: Física | D7: Reunião
A8: Geografia | B8: Geografia | D8: Recuperação
A9: História | B9: História | D9: Outro
A10: Inglês | B10: Inglês
A11: LP | B11: LP
A12: Matemática | B12: Matemática
A13: Projeto de vida | B13: Projeto de vida
A14: Química | B14: Química
A15: Sociologia | B15: Sociologia
A16: Oficinas | B16: Oficinas
B17: Coordenação
B18: Direção
B19: Orientação
B20: Secretaria
B21: Todas as disciplinas
